Workbook

Sheet Summary
A1: Medical / Hospital Architectural Program Summary
A3: Department | B3: Net Sq. Feet | C3: Grossing Factor | D3: Gross Sq. Feet | E3: Floor(s) | F3: Program Count
A4: Typical Bed Unit-32 ICU | B4: ='Typical Bed Unit-32 ICU'!C3 -> 16210 | C4: 1.59 | D4: ='Typical Bed Unit-32 ICU'!C5 -> 25773.9 | E4: 5 | F4: 19
A5: Emergency Department | B5: ='Emergency Department'!C3 -> 20350 | C5: 1.41 | D5: ='Emergency Department'!C5 -> 28693.5 | E5: 1 | F5: 26
A6: Imaging and Diagnostics | B6: ='Imaging and Diagnostics'!C3 -> 14530 | C6: 1.48 | D6: ='Imaging and Diagnostics'!C5 -> 21504.4 | E6: 1 | F6: 19
A7: Surgery and Operating Suite | B7: ='Surgery and Operating Suite'!C3 -> 30990 | C7: 1.47 | D7: ='Surgery and Operating Suite'!C5 -> 45555.3 | E7: 2 | F7: 22
A8: Endoscopy / GI | B8: ='Endoscopy and GI'!C3 -> 10240 | C8: 1.62 | D8: ='Endoscopy and GI'!C5 -> 16588.8 | E8: 2 | F8: 15
A9: Labor and Delivery | B9: ='Labor and Delivery'!C3 -> 14120 | C9: 1.6 | D9: ='Labor and Delivery'!C5 -> 22592 | E9: 3 | F9: 16
A10: NICU | B10: =NICU!C3 -> 15030 | C10: 1.67 | D10: =NICU!C5 -> 25100.1 | E10: 3 | F10: 14
A11: Medical Surgical Unit | B11: ='Medical Surgical Unit'!C3 -> 19860 | C11: 1.43 | D11: ='Medical Surgical Unit'!C5 -> 28399.8 | E11: 4 | F11: 15
A12: Cardiology and Cath Lab | B12: ='Cardiology and Cath Lab'!C3 -> 11360 | C12: 1.53 | D12: ='Cardiology and Cath Lab'!C5 -> 17380.8 | E12: 2 | F12: 14
A13: Oncology Center | B13: ='Oncology Center'!C3 -> 10340 | C13: 1.41 | D13: ='Oncology Center'!C5 -> 14579.4 | E13: 1 | F13: 15
A14: Behavioral Health | B14: ='Behavioral Health'!C3 -> 10910 | C14: 1.47 | D14: ='Behavioral Health'!C5 -> 16037.7 | E14: 6 | F14: 15
A15: Rehabilitation Therapy | B15: ='Rehabilitation Therapy'!C3 -> 5715 | C15: 1.55 | D15: ='Rehabilitation Therapy'!C5 -> 8858.25 | E15: 1 | F15: 12
A16: Clinical Laboratory | B16: ='Clinical Laboratory'!C3 -> 6410 | C16: 1.41 | D16: ='Clinical Laboratory'!C5 -> 9038.1 | E16: 1 | F16: 15
A17: Pharmacy | B17: =Pharmacy!C3 -> 5170 | C17: 1.46 | D17: =Pharmacy!C5 -> 7548.2 | E17: 1 | F17: 13
A18: Central Sterile Processing | B18: ='Central Sterile Processing'!C3 -> 6530 | C18: 1.59 | D18: ='Central Sterile Processing'!C5 -> 10382.7 | E18: 1 | F18: 13
A19: Ambulatory Clinics | B19: ='Ambulatory Clinics'!C3 -> 14130 | C19: 1.56 | D19: ='Ambulatory Clinics'!C5 -> 22042.8 | E19: 1 | F19: 13
A20: Public Amenities | B20: ='Public Amenities'!C3 -> 12830 | C20: 1.47 | D20: ='Public Amenities'!C5 -> 18860.1 | E20: 1 | F20: 13
A21: Administration | B21: =Administration!C3 -> 10470 | C21: 1.58 | D21: =Administration!C5 -> 16542.6 | E21: 7 | F21: 10
A22: Nutrition and Food Service | B22: ='Nutrition and Food Service'!C3 -> 10040 | C22: 1.64 | D22: ='Nutrition and Food Service'!C5 -> 16465.6 | E22: 1 | F22: 14
A23: Materials Management | B23: ='Materials Management'!C3 -> 10910 | C23: 1.4 | D23: ='Materials Management'!C5 -> 15274 | E23: 1 | F23: 12
A24: Environmental Services | B24: ='Environmental Services'!C3 -> 5890 | C24: 1.64 | D24: ='Environmental Services'!C5 -> 9659.6 | E24: 1 | F24: 11
A25: Facilities MEP and HVAC | B25: ='Facilities MEP and HVAC'!C3 -> 21740 | C25: 1.61 | D25: ='Facilities MEP and HVAC'!C5 -> 35001.4 | E25: 1 | F25: 18
A26: IT Security and Command Center | B26: ='IT Security and Command Center'!C3 -> 7310 | C26: 1.5 | D26: ='IT Security and Command Center'!C5 -> 10965 | E26: 1 | F26: 12
A27: Education and Conference | B27: ='Education and Conference'!C3 -> 10270 | C27: 1.45 | D27: ='Education and Conference'!C5 -> 14891.5 | E27: 7 | F27: 11
A28: Renal Dialysis | B28: ='Renal Dialysis'!C3 -> 6075 | C28: 1.69 | D28: ='Renal Dialysis'!C5 -> 10266.75 | E28: 1 | F28: 13
A30: TOTAL | B30: =SUM(B4:B28) -> 307430 | D30: =SUM(D4:D28) -> 468002.3

Sheet Typical Bed Unit-32 ICU
B3: Departmental Net Sq. Feet: | C3: =SUM(D15,D26,D35) -> 16210 | D3: Macro Program Placeholder: | E3: =C5 -> 25773.9
B4: Departmental Grossing Factor: | C4: 1.59
B5: Departmental Gross Sq. Feet: | C5: =C3*C4 -> 25773.9
A8: Program | B8: Quantity | C8: NSF/Room | D8: Total NSF | E8: Floor | F8: Comment
A9: Public Area
A10: Waiting, Public | B10: 1 | C10: 500 | D10: =B10*C10 -> 500 | E10: 5 | F10: Family lounge near elevator lobby
A11: Consult Room | B11: 3 | C11: 120 | D11: =B11*C11 -> 360 | E11: 5 | F11: Acoustic privacy required
A12: Public Toilet | B12: 4 | C12: 65 | D12: =B12*C12 -> 260 | E12: 5
A13: Reception / Check-in | B13: 1 | C13: 120 | D13: =B13*C13 -> 120 | E13: 5 | F13: Unit secretary
A14: Nourishment Area | B14: 1 | C14: 80 | D14: =B14*C14 -> 80 | E14: 5 | F14: Accessible to families
C15: NSF Subtotal: | D15: =SUM(D10:D14) -> 1320
A17: Patient Care
A18: ICU Patient Room | B18: 28 | C18: 300 | D18: =B18*C18 -> 8400 | E18: 5 | F18: All rooms med gas and headwall
A19: Isolation ICU Room | B19: 4 | C19: 320 | D19: =B19*C19 -> 1280 | E19: 5 | F19: Negative pressure capability
A20: Patient Toilet/Shower | B20: 32 | C20: 60 | D20: =B20*C20 -> 1920 | E20: 5
A21: Decentralized Charting Station | B21: 8 | C21: 45 | D21: =B21*C21 -> 360 | E21: 5 | F21: 1 per 4 rooms
A22: Medication Alcove | B22: 4 | C22: 60 | D22: =B22*C22 -> 240 | E22: 5
A23: Equipment Alcove | B23: 8 | C23: 40 | D23: =B23*C23 -> 320 | E23: 5 | F23: Crash cart access
A24: Clean Supply | B24: 2 | C24: 180 | D24: =B24*C24 -> 360 | E24: 5
A25: Soiled Utility | B25: 2 | C25: 160 | D25: =B25*C25 -> 320 | E25: 5
C26: NSF Subtotal: | D26: =SUM(D18:D25) -> 13200
A28: Staff Support
A29: Nurse Station | B29: 2 | C29: 240 | D29: =B29*C29 -> 480 | E29: 5 | F29: Direct sight lines to corridors
A30: Team Workroom | B30: 1 | C30: 300 | D30: =B30*C30 -> 300 | E30: 5
A31: Staff Lounge | B31: 1 | C31: 280 | D31: =B31*C31 -> 280 | E31: 5 | F31: Near staff elevators
A32: Staff Toilet | B32: 2 | C32: 55 | D32: =B32*C32 -> 110 | E32: 5
A33: On-call Room | B33: 2 | C33: 120 | D33: =B33*C33 -> 240 | E33: 5
A34: Medication Room | B34: 2 | C34: 140 | D34: =B34*C34 -> 280 | E34: 5 | F34: Secure access
C35: NSF Subtotal: | D35: =SUM(D29:D34) -> 1690
C37: NSF Subtotal: | D37: =C3 -> 16210
C38: Grossing Factor: | D38: =C4 -> 1.59
C39: DGSF Subtotal: | D39: =C5 -> 25773.9

Sheet Emergency Department
A1: Emergency Department
B3: Departmental Net Sq. Feet: | C3: =SUM(D17,D25,D35,D45) -> 20350 | D3: Macro Program Placeholder: | E3: =C5 -> 28693.5
B4: Departmental Grossing Factor: | C4: 1.41
B5: Departmental Gross Sq. Feet: | C5: =C3*C4 -> 28693.5
A8: Program | B8: Quantity | C8: NSF/Room | D8: Total NSF | E8: Floor | F8: Comment
A9: Public Area
A10: Ambulance Entry Vestibule | B10: 1 | C10: 220 | D10: =B10*C10 -> 220 | E10: 1 | F10: Weather protected
A11: Walk-in Entry Vestibule | B11: 1 | C11: 180 | D11: =B11*C11 -> 180 | E11: 1 | F11: Security screening
A12: Waiting, Adult | B12: 1 | C12: 900 | D12: =B12*C12 -> 900 | E12: 1 | F12: Visible from reception
A13: Waiting, Pediatric | B13: 1 | C13: 420 | D13: =B13*C13 -> 420 | E13: 1 | F13: Separate from adult waiting
A14: Triage Reception | B14: 4 | C14: 100 | D14: =B14*C14 -> 400 | E14: 1 | F14: Rapid intake
A15: Public Toilet | B15: 8 | C15: 65 | D15: =B15*C15 -> 520 | E15: 1 | F15: Distributed
A16: Family Consult Room | B16: 3 | C16: 120 | D16: =B16*C16 -> 360 | E16: 1 | F16: Quiet rooms
C17: NSF Subtotal: | D17: =SUM(D10:D16) -> 3000
A19: Triage & Intake
A20: Triage Bay | B20: 6 | C20: 140 | D20: =B20*C20 -> 840 | E20: 1 | F20: Direct route to treatment
A21: Registration Workstation | B21: 6 | C21: 60 | D21: =B21*C21 -> 360 | E21: 1 | F21: Adjacent to waiting
A22: Vitals Alcove | B22: 4 | C22: 70 | D22: =B22*C22 -> 280 | E22: 1
A23: Interview Room | B23: 4 | C23: 100 | D23: =B23*C23 -> 400 | E23: 1
A24: Security Room | B24: 1 | C24: 160 | D24: =B24*C24 -> 160 | E24: 1 | F24: View to entry
C25: NSF Subtotal: | D25: =SUM(D20:D24) -> 2040
A27: Treatment
A28: Exam/Treatment Room | B28: 32 | C28: 150 | D28: =B28*C28 -> 4800 | E28: 1 | F28: Universal exam bays
A29: Trauma/Resuscitation Bay | B29: 6 | C29: 300 | D29: =B29*C29 -> 1800 | E29: 1 | F29: Booms and imaging clearances
A30: Isolation Treatment Room | B30: 6 | C30: 180 | D30: =B30*C30 -> 1080 | E30: 1 | F30: Negative pressure
A31: Behavioral Health Holding Room | B31: 8 | C31: 140 | D31: =B31*C31 -> 1120 | E31: 1 | F31: Ligature-resistant
A32: Fast Track Exam | B32: 10 | C32: 120 | D32: =B32*C32 -> 1200 | E32: 1 | F32: Lower-acuity zone
A33: Procedure Room | B33: 3 | C33: 220 | D33: =B33*C33 -> 660 | E33: 1 | F33: Suture and casting
A34: Nurse Station | B34: 4 | C34: 260 | D34: =B34*C34 -> 1040 | E34: 1 | F34: Centralized pods
C35: NSF Subtotal: | D35: =SUM(D28:D34) -> 11700
A37: Clinical Support
A38: Medication Room | B38: 3 | C38: 140 | D38: =B38*C38 -> 420 | E38: 1 | F38: Secure access
A39: Clean Supply | B39: 4 | C39: 180 | D39: =B39*C39 -> 720 | E39: 1
A40: Soiled Utility | B40: 4 | C40: 160 | D40: =B40*C40 -> 640 | E40: 1
A41: Equipment Storage | B41: 3 | C41: 250 | D41: =B41*C41 -> 750 | E41: 1 | F41: Stretchers and monitors
A42: Point-of-Care Lab | B42: 1 | C42: 220 | D42: =B42*C42 -> 220 | E42: 1
A43: Staff Workroom | B43: 2 | C43: 240 | D43: =B43*C43 -> 480 | E43: 1
A44: Staff Lounge | B44: 1 | C44: 380 | D44: =B44*C44 -> 380 | E44: 1
C45: NSF Subtotal: | D45: =SUM(D38:D44) -> 3610
C47: NSF Subtotal: | D47: =C3 -> 20350
...

Sheet Imaging and Diagnostics
A1: Imaging and Diagnostics
B3: Departmental Net Sq. Feet: | C3: =SUM(D15,D25,D35) -> 14530 | D3: Macro Program Placeholder: | E3: =C5 -> 21504.4
B4: Departmental Grossing Factor: | C4: 1.48
B5: Departmental Gross Sq. Feet: | C5: =C3*C4 -> 21504.4
A8: Program | B8: Quantity | C8: NSF/Room | D8: Total NSF | E8: Floor | F8: Comment
A9: Public Area
A10: Reception / Check-in | B10: 1 | C10: 180 | D10: =B10*C10 -> 180 | E10: 1
A11: Waiting | B11: 1 | C11: 650 | D11: =B11*C11 -> 650 | E11: 1 | F11: Shared for modalities
A12: Changing Room | B12: 12 | C12: 55 | D12: =B12*C12 -> 660 | E12: 1 | F12: Gowned patient flow
A13: Patient Toilet | B13: 6 | C13: 60 | D13: =B13*C13 -> 360 | E13: 1
A14: Consult Room | B14: 2 | C14: 120 | D14: =B14*C14 -> 240 | E14: 1
C15: NSF Subtotal: | D15: =SUM(D10:D14) -> 2090
A17: Diagnostic Imaging
A18: General Radiography Room | B18: 4 | C18: 420 | D18: =B18*C18 -> 1680 | E18: 1 | F18: Control room adjacent
A19: CT Scanner Room | B19: 3 | C19: 550 | D19: =B19*C19 -> 1650 | E19: 1 | F19: Includes equipment clearances
A20: MRI Scanner Room | B20: 2 | C20: 700 | D20: =B20*C20 -> 1400 | E20: 1 | F20: Zone IV controlled access
A21: Ultrasound Room | B21: 6 | C21: 220 | D21: =B21*C21 -> 1320 | E21: 1
A22: Mammography Room | B22: 2 | C22: 220 | D22: =B22*C22 -> 440 | E22: 1
A23: Fluoroscopy Room | B23: 2 | C23: 500 | D23: =B23*C23 -> 1000 | E23: 1
A24: PET/CT Room | B24: 1 | C24: 650 | D24: =B24*C24 -> 650 | E24: 1 | F24: Shielding coordination
C25: NSF Subtotal: | D25: =SUM(D18:D24) -> 8140
A27: Imaging Support
A28: Control Room | B28: 9 | C28: 120 | D28: =B28*C28 -> 1080 | E28: 1 | F28: Shared by modality
A29: Equipment Room | B29: 6 | C29: 180 | D29: =B29*C29 -> 1080 | E29: 1 | F29: Vendor coordination
A30: Reading Room | B30: 2 | C30: 280 | D30: =B30*C30 -> 560 | E30: 1 | F30: Low light environment
A31: Image Processing | B31: 1 | C31: 220 | D31: =B31*C31 -> 220 | E31: 1
A32: Clean Supply | B32: 2 | C32: 140 | D32: =B32*C32 -> 280 | E32: 1
A33: Soiled Utility | B33: 2 | C33: 120 | D33: =B33*C33 -> 240 | E33: 1
A34: Stretcher Holding | B34: 12 | C34: 70 | D34: =B34*C34 -> 840 | E34: 1
C35: NSF Subtotal: | D35: =SUM(D28:D34) -> 4300
C37: NSF Subtotal: | D37: =C3 -> 14530
C38: Grossing Factor: | D38: =C4 -> 1.48
C39: DGSF Subtotal: | D39: =C5 -> 21504.4

Sheet Surgery and Operating Suite
A1: Surgery and Operating Suite
B3: Departmental Net Sq. Feet: | C3: =SUM(D14,D22,D31,D41) -> 30990 | D3: Macro Program Placeholder: | E3: =C5 -> 45555.3
B4: Departmental Grossing Factor: | C4: 1.47
B5: Departmental Gross Sq. Feet: | C5: =C3*C4 -> 45555.3
A8: Program | B8: Quantity | C8: NSF/Room | D8: Total NSF | E8: Floor | F8: Comment
A9: Surgical Public Area
A10: Surgical Waiting | B10: 1 | C10: 900 | D10: =B10*C10 -> 900 | E10: 2 | F10: Near family consult rooms
A11: Family Consult Room | B11: 6 | C11: 120 | D11: =B11*C11 -> 720 | E11: 2 | F11: Post-op conversations
A12: Reception | B12: 1 | C12: 180 | D12: =B12*C12 -> 180 | E12: 2
A13: Public Toilet | B13: 6 | C13: 65 | D13: =B13*C13 -> 390 | E13: 2
C14: NSF Subtotal: | D14: =SUM(D10:D13) -> 2190
A16: Pre-Op / PACU
A17: Pre-Op Bay | B17: 28 | C17: 110 | D17: =B17*C17 -> 3080 | E17: 2 | F17: Curtained bays
A18: PACU Phase I Bay | B18: 24 | C18: 130 | D18: =B18*C18 -> 3120 | E18: 2 | F18: Direct from OR core
A19: PACU Phase II Chair | B19: 20 | C19: 80 | D19: =B19*C19 -> 1600 | E19: 2 | F19: Discharge readiness
A20: Isolation Recovery Room | B20: 3 | C20: 160 | D20: =B20*C20 -> 480 | E20: 2
A21: Nurse Station | B21: 3 | C21: 220 | D21: =B21*C21 -> 660 | E21: 2
C22: NSF Subtotal: | D22: =SUM(D17:D21) -> 8940
A24: Operating Rooms
A25: General OR | B25: 12 | C25: 650 | D25: =B25*C25 -> 7800 | E25: 2 | F25: Booms and integrated imaging
A26: Hybrid OR | B26: 2 | C26: 900 | D26: =B26*C26 -> 1800 | E26: 2 | F26: Structural capacity required
A27: Robotics OR | B27: 2 | C27: 750 | D27: =B27*C27 -> 1500 | E27: 2 | F27: Robot storage nearby
A28: C-Section OR | B28: 2 | C28: 600 | D28: =B28*C28 -> 1200 | E28: 2 | F28: If linked to L&D
A29: Induction Room | B29: 4 | C29: 150 | D29: =B29*C29 -> 600 | E29: 2 | F29: Optional anesthesia induction
A30: Sub-Sterile Room | B30: 6 | C30: 120 | D30: =B30*C30 -> 720 | E30: 2 | F30: Between OR pairs
C31: NSF Subtotal: | D31: =SUM(D25:D30) -> 13620
A33: Sterile Core & Support
A34: Sterile Core | B34: 1 | C34: 2200 | D34: =B34*C34 -> 2200 | E34: 2 | F34: Restricted access
A35: Case Cart Staging | B35: 1 | C35: 600 | D35: =B35*C35 -> 600 | E35: 2
A36: Anesthesia Workroom | B36: 1 | C36: 350 | D36: =B36*C36 -> 350 | E36: 2
A37: Clean Supply | B37: 3 | C37: 300 | D37: =B37*C37 -> 900 | E37: 2
A38: Soiled Holding | B38: 2 | C38: 220 | D38: =B38*C38 -> 440 | E38: 2
A39: Staff Locker | B39: 2 | C39: 650 | D39: =B39*C39 -> 1300 | E39: 2 | F39: Male/female-neutral lockers
A40: Staff Lounge | B40: 1 | C40: 450 | D40: =B40*C40 -> 450 | E40: 2
C41: NSF Subtotal: | D41: =SUM(D34:D40) -> 6240
C43: NSF Subtotal: | D43: =C3 -> 30990
C44: Grossing Factor: | D44: =C4 -> 1.47
C45: DGSF Subtotal: | D45: =C5 -> 45555.3

Sheet Endoscopy and GI
A1: Endoscopy / GI
B3: Departmental Net Sq. Feet: | C3: =SUM(D14,D22,D31) -> 10240 | D3: Macro Program Placeholder: | E3: =C5 -> 16588.8
B4: Departmental Grossing Factor: | C4: 1.62
B5: Departmental Gross Sq. Feet: | C5: =C3*C4 -> 16588.8
A8: Program | B8: Quantity | C8: NSF/Room | D8: Total NSF | E8: Floor | F8: Comment
A9: Public Area
A10: Reception | B10: 1 | C10: 160 | D10: =B10*C10 -> 160 | E10: 2
A11: Waiting | B11: 1 | C11: 500 | D11: =B11*C11 -> 500 | E11: 2
A12: Consult Room | B12: 2 | C12: 120 | D12: =B12*C12 -> 240 | E12: 2
A13: Public Toilet | B13: 4 | C13: 65 | D13: =B13*C13 -> 260 | E13: 2
C14: NSF Subtotal: | D14: =SUM(D10:D13) -> 1160
A16: Procedure
A17: Endoscopy Procedure Room | B17: 8 | C17: 300 | D17: =B17*C17 -> 2400 | E17: 2
A18: Bronchoscopy Procedure Room | B18: 2 | C18: 320 | D18: =B18*C18 -> 640 | E18: 2 | F18: Negative pressure option
A19: Scope Processing Room | B19: 1 | C19: 550 | D19: =B19*C19 -> 550 | E19: 2 | F19: Pass-through flow
A20: Clean Scope Storage | B20: 1 | C20: 250 | D20: =B20*C20 -> 250 | E20: 2
A21: Nurse Station | B21: 2 | C21: 180 | D21: =B21*C21 -> 360 | E21: 2
C22: NSF Subtotal: | D22: =SUM(D17:D21) -> 4200
A24: Prep / Recovery
A25: Prep Bay | B25: 18 | C25: 100 | D25: =B25*C25 -> 1800 | E25: 2
A26: Recovery Bay | B26: 18 | C26: 110 | D26: =B26*C26 -> 1980 | E26: 2
A27: Patient Toilet | B27: 6 | C27: 60 | D27: =B27*C27 -> 360 | E27: 2
A28: Clean Supply | B28: 2 | C28: 120 | D28: =B28*C28 -> 240 | E28: 2
A29: Soiled Utility | B29: 2 | C29: 120 | D29: =B29*C29 -> 240 | E29: 2
A30: Equipment Storage | B30: 1 | C30: 260 | D30: =B30*C30 -> 260 | E30: 2
C31: NSF Subtotal: | D31: =SUM(D25:D30) -> 4880
C33: NSF Subtotal: | D33: =C3 -> 10240
C34: Grossing Factor: | D34: =C4 -> 1.62
C35: DGSF Subtotal: | D35: =C5 -> 16588.8

Sheet Labor and Delivery
A1: Labor and Delivery
B3: Departmental Net Sq. Feet: | C3: =SUM(D14,D23,D32) -> 14120 | D3: Macro Program Placeholder: | E3: =C5 -> 22592
B4: Departmental Grossing Factor: | C4: 1.6
B5: Departmental Gross Sq. Feet: | C5: =C3*C4 -> 22592
A8: Program | B8: Quantity | C8: NSF/Room | D8: Total NSF | E8: Floor | F8: Comment
A9: Public Area
A10: Waiting, Family | B10: 1 | C10: 620 | D10: =B10*C10 -> 620 | E10: 3
A11: Reception / Check-in | B11: 1 | C11: 160 | D11: =B11*C11 -> 160 | E11: 3
A12: Consult Room | B12: 2 | C12: 120 | D12: =B12*C12 -> 240 | E12: 3
A13: Public Toilet | B13: 4 | C13: 65 | D13: =B13*C13 -> 260 | E13: 3
C14: NSF Subtotal: | D14: =SUM(D10:D13) -> 1280
A16: Birthing Care
A17: LDR Room | B17: 18 | C17: 330 | D17: =B17*C17 -> 5940 | E17: 3 | F17: Labor/delivery/recovery
A18: Antepartum Room | B18: 8 | C18: 260 | D18: =B18*C18 -> 2080 | E18: 3
A19: Triage Room | B19: 6 | C19: 180 | D19: =B19*C19 -> 1080 | E19: 3
A20: C-Section OR | B20: 2 | C20: 600 | D20: =B20*C20 -> 1200 | E20: 3 | F20: Adjacent to LDR zone
A21: Newborn Stabilization | B21: 2 | C21: 180 | D21: =B21*C21 -> 360 | E21: 3
A22: Nurse Station | B22: 2 | C22: 260 | D22: =B22*C22 -> 520 | E22: 3
C23: NSF Subtotal: | D23: =SUM(D17:D22) -> 11180
A25: Support
A26: Clean Supply | B26: 2 | C26: 180 | D26: =B26*C26 -> 360 | E26: 3
A27: Soiled Utility | B27: 2 | C27: 160 | D27: =B27*C27 -> 320 | E27: 3
A28: Medication Room | B28: 2 | C28: 140 | D28: =B28*C28 -> 280 | E28: 3
A29: Formula / Nourishment | B29: 1 | C29: 120 | D29: =B29*C29 -> 120 | E29: 3
A30: Equipment Storage | B30: 1 | C30: 280 | D30: =B30*C30 -> 280 | E30: 3
A31: Staff Lounge | B31: 1 | C31: 300 | D31: =B31*C31 -> 300 | E31: 3
C32: NSF Subtotal: | D32: =SUM(D26:D31) -> 1660
C34: NSF Subtotal: | D34: =C3 -> 14120
C35: Grossing Factor: | D35: =C4 -> 1.6
C36: DGSF Subtotal: | D36: =C5 -> 22592

Sheet NICU
A1: NICU
B3: Departmental Net Sq. Feet: | C3: =SUM(D14,D22,D30) -> 15030 | D3: Macro Program Placeholder: | E3: =C5 -> 25100.1
B4: Departmental Grossing Factor: | C4: 1.67
B5: Departmental Gross Sq. Feet: | C5: =C3*C4 -> 25100.1
A8: Program | B8: Quantity | C8: NSF/Room | D8: Total NSF | E8: Floor | F8: Comment
A9: Family Area
A10: Family Waiting | B10: 1 | C10: 400 | D10: =B10*C10 -> 400 | E10: 3
A11: Family Consult Room | B11: 3 | C11: 120 | D11: =B11*C11 -> 360 | E11: 3
A12: Lactation Room | B12: 4 | C12: 100 | D12: =B12*C12 -> 400 | E12: 3
A13: Parent Sleep Room | B13: 6 | C13: 120 | D13: =B13*C13 -> 720 | E13: 3
C14: NSF Subtotal: | D14: =SUM(D10:D13) -> 1880
A16: Neonatal Care
A17: NICU Single-Family Room | B17: 36 | C17: 250 | D17: =B17*C17 -> 9000 | E17: 3
A18: Isolation NICU Room | B18: 4 | C18: 270 | D18: =B18*C18 -> 1080 | E18: 3
A19: Procedure Room | B19: 2 | C19: 220 | D19: =B19*C19 -> 440 | E19: 3
A20: Nurse Station | B20: 3 | C20: 220 | D20: =B20*C20 -> 660 | E20: 3
A21: Medication Room | B21: 2 | C21: 120 | D21: =B21*C21 -> 240 | E21: 3
C22: NSF Subtotal: | D22: =SUM(D17:D21) -> 11420
A24: NICU Support
A25: Clean Supply | B25: 2 | C25: 180 | D25: =B25*C25 -> 360 | E25: 3
A26: Soiled Utility | B26: 2 | C26: 150 | D26: =B26*C26 -> 300 | E26: 3
A27: Equipment Storage | B27: 2 | C27: 280 | D27: =B27*C27 -> 560 | E27: 3
A28: Formula Prep | B28: 1 | C28: 250 | D28: =B28*C28 -> 250 | E28: 3 | F28: Controlled environment
A29: Staff Workroom | B29: 1 | C29: 260 | D29: =B29*C29 -> 260 | E29: 3
C30: NSF Subtotal: | D30: =SUM(D25:D29) -> 1730
C32: NSF Subtotal: | D32: =C3 -> 15030
C33: Grossing Factor: | D33: =C4 -> 1.67
C34: DGSF Subtotal: | D34: =C5 -> 25100.1

Sheet Medical Surgical Unit
A1: Medical Surgical Unit
B3: Departmental Net Sq. Feet: | C3: =SUM(D14,D22,D31) -> 19860 | D3: Macro Program Placeholder: | E3: =C5 -> 28399.8
B4: Departmental Grossing Factor: | C4: 1.43
B5: Departmental Gross Sq. Feet: | C5: =C3*C4 -> 28399.8
A8: Program | B8: Quantity | C8: NSF/Room | D8: Total NSF | E8: Floor | F8: Comment
A9: Public Area
A10: Unit Waiting | B10: 1 | C10: 420 | D10: =B10*C10 -> 420 | E10: 4
A11: Family Consult Room | B11: 2 | C11: 120 | D11: =B11*C11 -> 240 | E11: 4
A12: Public Toilet | B12: 2 | C12: 65 | D12: =B12*C12 -> 130 | E12: 4
A13: Reception | B13: 1 | C13: 120 | D13: =B13*C13 -> 120 | E13: 4
C14: NSF Subtotal: | D14: =SUM(D10:D13) -> 910
A16: Patient Care
A17: Med/Surg Patient Room | B17: 48 | C17: 230 | D17: =B17*C17 -> 11040 | E17: 4 | F17: Universal rooms
A18: Isolation Patient Room | B18: 6 | C18: 260 | D18: =B18*C18 -> 1560 | E18: 4
A19: Patient Toilet/Shower | B19: 54 | C19: 55 | D19: =B19*C19 -> 2970 | E19: 4
A20: Nurse Station | B20: 3 | C20: 240 | D20: =B20*C20 -> 720 | E20: 4
A21: Charting Alcove | B21: 12 | C21: 35 | D21: =B21*C21 -> 420 | E21: 4
C22: NSF Subtotal: | D22: =SUM(D17:D21) -> 16710
A24: Support
A25: Medication Room | B25: 3 | C25: 120 | D25: =B25*C25 -> 360 | E25: 4
A26: Clean Supply | B26: 3 | C26: 160 | D26: =B26*C26 -> 480 | E26: 4
A27: Soiled Utility | B27: 3 | C27: 140 | D27: =B27*C27 -> 420 | E27: 4
A28: Equipment Storage | B28: 2 | C28: 220 | D28: =B28*C28 -> 440 | E28: 4
A29: Staff Lounge | B29: 1 | C29: 320 | D29: =B29*C29 -> 320 | E29: 4
A30: Staff Toilet | B30: 4 | C30: 55 | D30: =B30*C30 -> 220 | E30: 4
C31: NSF Subtotal: | D31: =SUM(D25:D30) -> 2240
C33: NSF Subtotal: | D33: =C3 -> 19860
C34: Grossing Factor: | D34: =C4 -> 1.43
C35: DGSF Subtotal: | D35: =C5 -> 28399.8

Sheet Cardiology and Cath Lab
A1: Cardiology and Cath Lab
B3: Departmental Net Sq. Feet: | C3: =SUM(D14,D22,D30) -> 11360 | D3: Macro Program Placeholder: | E3: =C5 -> 17380.8
B4: Departmental Grossing Factor: | C4: 1.53
B5: Departmental Gross Sq. Feet: | C5: =C3*C4 -> 17380.8
A8: Program | B8: Quantity | C8: NSF/Room | D8: Total NSF | E8: Floor | F8: Comment
A9: Public Area
A10: Reception | B10: 1 | C10: 160 | D10: =B10*C10 -> 160 | E10: 2
A11: Waiting | B11: 1 | C11: 550 | D11: =B11*C11 -> 550 | E11: 2
A12: Consult Room | B12: 3 | C12: 120 | D12: =B12*C12 -> 360 | E12: 2
A13: Public Toilet | B13: 4 | C13: 65 | D13: =B13*C13 -> 260 | E13: 2
C14: NSF Subtotal: | D14: =SUM(D10:D13) -> 1330
A16: Cath / EP Procedure
A17: Cardiac Cath Lab | B17: 4 | C17: 650 | D17: =B17*C17 -> 2600 | E17: 2 | F17: Control room adjacent
A18: Electrophysiology Lab | B18: 2 | C18: 700 | D18: =B18*C18 -> 1400 | E18: 2 | F18: Shielding required
A19: Echo Room | B19: 4 | C19: 220 | D19: =B19*C19 -> 880 | E19: 2
A20: Stress Test Room | B20: 3 | C20: 250 | D20: =B20*C20 -> 750 | E20: 2
A21: Device Clinic Room | B21: 3 | C21: 140 | D21: =B21*C21 -> 420 | E21: 2
C22: NSF Subtotal: | D22: =SUM(D17:D21) -> 6050
A24: Prep / Recovery
A25: Prep/Recovery Bay | B25: 24 | C25: 110 | D25: =B25*C25 -> 2640 | E25: 2
A26: Nurse Station | B26: 2 | C26: 220 | D26: =B26*C26 -> 440 | E26: 2
A27: Clean Supply | B27: 2 | C27: 160 | D27: =B27*C27 -> 320 | E27: 2
A28: Soiled Utility | B28: 2 | C28: 140 | D28: =B28*C28 -> 280 | E28: 2
A29: Equipment Storage | B29: 1 | C29: 300 | D29: =B29*C29 -> 300 | E29: 2
C30: NSF Subtotal: | D30: =SUM(D25:D29) -> 3980
C32: NSF Subtotal: | D32: =C3 -> 11360
C33: Grossing Factor: | D33: =C4 -> 1.53
C34: DGSF Subtotal: | D34: =C5 -> 17380.8

Sheet Oncology Center
A1: Oncology Center
B3: Departmental Net Sq. Feet: | C3: =SUM(D15,D23,D31) -> 10340 | D3: Macro Program Placeholder: | E3: =C5 -> 14579.4
B4: Departmental Grossing Factor: | C4: 1.41
B5: Departmental Gross Sq. Feet: | C5: =C3*C4 -> 14579.4
A8: Program | B8: Quantity | C8: NSF/Room | D8: Total NSF | E8: Floor | F8: Comment
A9: Public Area
A10: Reception | B10: 1 | C10: 180 | D10: =B10*C10 -> 180 | E10: 1
A11: Waiting | B11: 1 | C11: 700 | D11: =B11*C11 -> 700 | E11: 1 | F11: Daylight preferred
A12: Resource Library | B12: 1 | C12: 180 | D12: =B12*C12 -> 180 | E12: 1
A13: Consult Room | B13: 4 | C13: 120 | D13: =B13*C13 -> 480 | E13: 1
A14: Public Toilet | B14: 6 | C14: 65 | D14: =B14*C14 -> 390 | E14: 1
C15: NSF Subtotal: | D15: =SUM(D10:D14) -> 1930
A17: Treatment
A18: Infusion Bay | B18: 36 | C18: 95 | D18: =B18*C18 -> 3420 | E18: 1 | F18: Recliner-based care
A19: Private Infusion Room | B19: 8 | C19: 140 | D19: =B19*C19 -> 1120 | E19: 1
A20: Exam Room | B20: 12 | C20: 120 | D20: =B20*C20 -> 1440 | E20: 1
A21: Procedure Room | B21: 2 | C21: 200 | D21: =B21*C21 -> 400 | E21: 1
A22: Nurse Station | B22: 3 | C22: 220 | D22: =B22*C22 -> 660 | E22: 1
C23: NSF Subtotal: | D23: =SUM(D18:D22) -> 7040
A25: Pharmacy Support
A26: Chemo Prep Cleanroom | B26: 1 | C26: 450 | D26: =B26*C26 -> 450 | E26: 1 | F26: USP compliant
A27: Hazardous Drug Storage | B27: 1 | C27: 160 | D27: =B27*C27 -> 160 | E27: 1
A28: Medication Room | B28: 2 | C28: 120 | D28: =B28*C28 -> 240 | E28: 1
A29: Clean Supply | B29: 2 | C29: 140 | D29: =B29*C29 -> 280 | E29: 1
A30: Soiled Utility | B30: 2 | C30: 120 | D30: =B30*C30 -> 240 | E30: 1
C31: NSF Subtotal: | D31: =SUM(D26:D30) -> 1370
C33: NSF Subtotal: | D33: =C3 -> 10340
C34: Grossing Factor: | D34: =C4 -> 1.41
C35: DGSF Subtotal: | D35: =C5 -> 14579.4

Sheet Behavioral Health
A1: Behavioral Health
B3: Departmental Net Sq. Feet: | C3: =SUM(D14,D23,D31) -> 10910 | D3: Macro Program Placeholder: | E3: =C5 -> 16037.7
B4: Departmental Grossing Factor: | C4: 1.47
B5: Departmental Gross Sq. Feet: | C5: =C3*C4 -> 16037.7
A8: Program | B8: Quantity | C8: NSF/Room | D8: Total NSF | E8: Floor | F8: Comment
A9: Secure Public Area
A10: Controlled Entry | B10: 1 | C10: 180 | D10: =B10*C10 -> 180 | E10: 6 | F10: Staff-controlled
A11: Family Waiting | B11: 1 | C11: 300 | D11: =B11*C11 -> 300 | E11: 6
A12: Interview Room | B12: 3 | C12: 120 | D12: =B12*C12 -> 360 | E12: 6 | F12: Ligature-resistant
A13: Visitor Toilet | B13: 2 | C13: 60 | D13: =B13*C13 -> 120 | E13: 6
C14: NSF Subtotal: | D14: =SUM(D10:D13) -> 960
A16: Inpatient Behavioral Health
A17: Patient Room | B17: 24 | C17: 190 | D17: =B17*C17 -> 4560 | E17: 6 | F17: Anti-ligature design
A18: Patient Toilet/Shower | B18: 24 | C18: 55 | D18: =B18*C18 -> 1320 | E18: 6
A19: Quiet Room | B19: 4 | C19: 120 | D19: =B19*C19 -> 480 | E19: 6
A20: Seclusion Room | B20: 2 | C20: 160 | D20: =B20*C20 -> 320 | E20: 6 | F20: Observation required
A21: Group Therapy Room | B21: 3 | C21: 400 | D21: =B21*C21 -> 1200 | E21: 6
A22: Dining / Day Room | B22: 1 | C22: 900 | D22: =B22*C22 -> 900 | E22: 6
C23: NSF Subtotal: | D23: =SUM(D17:D22) -> 8780
A25: Staff and Support
A26: Nurse Station | B26: 2 | C26: 260 | D26: =B26*C26 -> 520 | E26: 6 | F26: Secure desk
A27: Medication Room | B27: 1 | C27: 130 | D27: =B27*C27 -> 130 | E27: 6
A28: Clean Supply | B28: 1 | C28: 150 | D28: =B28*C28 -> 150 | E28: 6
A29: Soiled Utility | B29: 1 | C29: 130 | D29: =B29*C29 -> 130 | E29: 6
A30: Staff Workroom | B30: 1 | C30: 240 | D30: =B30*C30 -> 240 | E30: 6
C31: NSF Subtotal: | D31: =SUM(D26:D30) -> 1170
C33: NSF Subtotal: | D33: =C3 -> 10910
C34: Grossing Factor: | D34: =C4 -> 1.47
C35: DGSF Subtotal: | D35: =C5 -> 16037.7

Sheet Rehabilitation Therapy
A1: Rehabilitation Therapy
B3: Departmental Net Sq. Feet: | C3: =SUM(D13,D21,D28) -> 5715 | D3: Macro Program Placeholder: | E3: =C5 -> 8858.25
B4: Departmental Grossing Factor: | C4: 1.55
B5: Departmental Gross Sq. Feet: | C5: =C3*C4 -> 8858.25
A8: Program | B8: Quantity | C8: NSF/Room | D8: Total NSF | E8: Floor | F8: Comment
A9: Public Area
A10: Reception | B10: 1 | C10: 140 | D10: =B10*C10 -> 140 | E10: 1
A11: Waiting | B11: 1 | C11: 350 | D11: =B11*C11 -> 350 | E11: 1
A12: Public Toilet | B12: 3 | C12: 65 | D12: =B12*C12 -> 195 | E12: 1
C13: NSF Subtotal: | D13: =SUM(D10:D12) -> 685
A15: Therapy
A16: Physical Therapy Gym | B16: 1 | C16: 1800 | D16: =B16*C16 -> 1800 | E16: 1 | F16: Open treatment area
A17: Occupational Therapy ADL Suite | B17: 1 | C17: 550 | D17: =B17*C17 -> 550 | E17: 1 | F17: Mock apartment
A18: Speech Therapy Room | B18: 4 | C18: 120 | D18: =B18*C18 -> 480 | E18: 1
A19: Private Treatment Room | B19: 8 | C19: 110 | D19: =B19*C19 -> 880 | E19: 1
A20: Hydrotherapy Room | B20: 1 | C20: 300 | D20: =B20*C20 -> 300 | E20: 1
C21: NSF Subtotal: | D21: =SUM(D16:D20) -> 4010
A23: Support
A24: Equipment Storage | B24: 2 | C24: 250 | D24: =B24*C24 -> 500 | E24: 1
A25: Clean Supply | B25: 1 | C25: 120 | D25: =B25*C25 -> 120 | E25: 1
A26: Staff Workroom | B26: 1 | C26: 220 | D26: =B26*C26 -> 220 | E26: 1
A27: Staff Lockers | B27: 1 | C27: 180 | D27: =B27*C27 -> 180 | E27: 1
C28: NSF Subtotal: | D28: =SUM(D24:D27) -> 1020
C30: NSF Subtotal: | D30: =C3 -> 5715
C31: Grossing Factor: | D31: =C4 -> 1.55
C32: DGSF Subtotal: | D32: =C5 -> 8858.25

Sheet Clinical Laboratory
A1: Clinical Laboratory
B3: Departmental Net Sq. Feet: | C3: =SUM(D14,D23,D31) -> 6410 | D3: Macro Program Placeholder: | E3: =C5 -> 9038.1
B4: Departmental Grossing Factor: | C4: 1.41
B5: Departmental Gross Sq. Feet: | C5: =C3*C4 -> 9038.1
A8: Program | B8: Quantity | C8: NSF/Room | D8: Total NSF | E8: Floor | F8: Comment
A9: Specimen Collection
A10: Reception | B10: 1 | C10: 140 | D10: =B10*C10 -> 140 | E10: 1
A11: Phlebotomy Bay | B11: 8 | C11: 80 | D11: =B11*C11 -> 640 | E11: 1
A12: Patient Toilet | B12: 2 | C12: 60 | D12: =B12*C12 -> 120 | E12: 1
A13: Waiting | B13: 1 | C13: 300 | D13: =B13*C13 -> 300 | E13: 1
C14: NSF Subtotal: | D14: =SUM(D10:D13) -> 1200
A16: Core Laboratory
A17: Hematology Lab | B17: 1 | C17: 700 | D17: =B17*C17 -> 700 | E17: 1
A18: Chemistry Lab | B18: 1 | C18: 900 | D18: =B18*C18 -> 900 | E18: 1
A19: Microbiology Lab | B19: 1 | C19: 800 | D19: =B19*C19 -> 800 | E19: 1 | F19: Controlled access
A20: Blood Bank | B20: 1 | C20: 550 | D20: =B20*C20 -> 550 | E20: 1
A21: Molecular Diagnostics | B21: 1 | C21: 600 | D21: =B21*C21 -> 600 | E21: 1
A22: Specimen Processing | B22: 1 | C22: 450 | D22: =B22*C22 -> 450 | E22: 1
C23: NSF Subtotal: | D23: =SUM(D17:D22) -> 4000
A25: Lab Support
A26: Cold Room | B26: 2 | C26: 160 | D26: =B26*C26 -> 320 | E26: 1
A27: Reagent Storage | B27: 1 | C27: 250 | D27: =B27*C27 -> 250 | E27: 1
A28: Glasswash / Sterilization | B28: 1 | C28: 220 | D28: =B28*C28 -> 220 | E28: 1
A29: Waste Holding | B29: 1 | C29: 160 | D29: =B29*C29 -> 160 | E29: 1
A30: Staff Workroom | B30: 1 | C30: 260 | D30: =B30*C30 -> 260 | E30: 1
C31: NSF Subtotal: | D31: =SUM(D26:D30) -> 1210
C33: NSF Subtotal: | D33: =C3 -> 6410
C34: Grossing Factor: | D34: =C4 -> 1.41
C35: DGSF Subtotal: | D35: =C5 -> 9038.1

Sheet Pharmacy
A1: Pharmacy
B3: Departmental Net Sq. Feet: | C3: =SUM(D14,D21,D29) -> 5170 | D3: Macro Program Placeholder: | E3: =C5 -> 7548.2
B4: Departmental Grossing Factor: | C4: 1.46
B5: Departmental Gross Sq. Feet: | C5: =C3*C4 -> 7548.2
A8: Program | B8: Quantity | C8: NSF/Room | D8: Total NSF | E8: Floor | F8: Comment
A9: Dispensing
A10: Inpatient Pharmacy | B10: 1 | C10: 1200 | D10: =B10*C10 -> 1200 | E10: 1 | F10: Central distribution
A11: Medication Carousel | B11: 1 | C11: 350 | D11: =B11*C11 -> 350 | E11: 1 | F11: Automated storage
A12: Unit Dose Packaging | B12: 1 | C12: 300 | D12: =B12*C12 -> 300 | E12: 1
A13: Pharmacist Workstations | B13: 12 | C13: 55 | D13: =B13*C13 -> 660 | E13: 1
C14: NSF Subtotal: | D14: =SUM(D10:D13) -> 2510
A16: Sterile Compounding
A17: IV Cleanroom | B17: 1 | C17: 550 | D17: =B17*C17 -> 550 | E17: 1 | F17: USP compliant
A18: Ante Room | B18: 1 | C18: 240 | D18: =B18*C18 -> 240 | E18: 1
A19: Hazardous Compounding Room | B19: 1 | C19: 350 | D19: =B19*C19 -> 350 | E19: 1 | F19: Negative pressure
A20: Chemo Storage | B20: 1 | C20: 180 | D20: =B20*C20 -> 180 | E20: 1
C21: NSF Subtotal: | D21: =SUM(D17:D20) -> 1320
A23: Support
A24: Receiving / Quarantine | B24: 1 | C24: 260 | D24: =B24*C24 -> 260 | E24: 1
A25: Bulk Drug Storage | B25: 1 | C25: 450 | D25: =B25*C25 -> 450 | E25: 1
A26: Secure Narcotics Room | B26: 1 | C26: 120 | D26: =B26*C26 -> 120 | E26: 1 | F26: Controlled access
A27: Office | B27: 4 | C27: 100 | D27: =B27*C27 -> 400 | E27: 1
A28: Staff Toilet | B28: 2 | C28: 55 | D28: =B28*C28 -> 110 | E28: 1
C29: NSF Subtotal: | D29: =SUM(D24:D28) -> 1340
C31: NSF Subtotal: | D31: =C3 -> 5170
C32: Grossing Factor: | D32: =C4 -> 1.46
C33: DGSF Subtotal: | D33: =C5 -> 7548.2

Sheet Central Sterile Processing
A1: Central Sterile Processing
B3: Departmental Net Sq. Feet: | C3: =SUM(D14,D22,D29) -> 6530 | D3: Macro Program Placeholder: | E3: =C5 -> 10382.7
B4: Departmental Grossing Factor: | C4: 1.59
B5: Departmental Gross Sq. Feet: | C5: =C3*C4 -> 10382.7
A8: Program | B8: Quantity | C8: NSF/Room | D8: Total NSF | E8: Floor | F8: Comment
A9: Decontamination
A10: Decontam Work Area | B10: 1 | C10: 900 | D10: =B10*C10 -> 900 | E10: 1 | F10: Dirty-to-clean flow
A11: Cart Wash | B11: 1 | C11: 450 | D11: =B11*C11 -> 450 | E11: 1
A12: Soiled Elevator Lobby | B12: 1 | C12: 220 | D12: =B12*C12 -> 220 | E12: 1
A13: Waste Holding | B13: 1 | C13: 160 | D13: =B13*C13 -> 160 | E13: 1
C14: NSF Subtotal: | D14: =SUM(D10:D13) -> 1730
A16: Preparation & Sterilization
A17: Prep and Pack | B17: 1 | C17: 1100 | D17: =B17*C17 -> 1100 | E17: 1
A18: Sterilizer Room | B18: 1 | C18: 700 | D18: =B18*C18 -> 700 | E18: 1 | F18: Steam and low-temp
A19: Sterile Storage | B19: 1 | C19: 1200 | D19: =B19*C19 -> 1200 | E19: 1 | F19: Controlled humidity
A20: Case Cart Assembly | B20: 1 | C20: 650 | D20: =B20*C20 -> 650 | E20: 1
A21: Instrument Repair | B21: 1 | C21: 200 | D21: =B21*C21 -> 200 | E21: 1
C22: NSF Subtotal: | D22: =SUM(D17:D21) -> 3850
A24: Support
A25: Staff Lockers | B25: 1 | C25: 300 | D25: =B25*C25 -> 300 | E25: 1
A26: Staff Workroom | B26: 1 | C26: 180 | D26: =B26*C26 -> 180 | E26: 1
A27: Supervisor Office | B27: 1 | C27: 120 | D27: =B27*C27 -> 120 | E27: 1
A28: Supply Storage | B28: 1 | C28: 350 | D28: =B28*C28 -> 350 | E28: 1
C29: NSF Subtotal: | D29: =SUM(D25:D28) -> 950
C31: NSF Subtotal: | D31: =C3 -> 6530
C32: Grossing Factor: | D32: =C4 -> 1.59
C33: DGSF Subtotal: | D33: =C5 -> 10382.7

Sheet Ambulatory Clinics
A1: Ambulatory Clinics
B3: Departmental Net Sq. Feet: | C3: =SUM(D14,D21,D29) -> 14130 | D3: Macro Program Placeholder: | E3: =C5 -> 22042.8
B4: Departmental Grossing Factor: | C4: 1.56
B5: Departmental Gross Sq. Feet: | C5: =C3*C4 -> 22042.8
A8: Program | B8: Quantity | C8: NSF/Room | D8: Total NSF | E8: Floor | F8: Comment
A9: Public Area
A10: Registration | B10: 1 | C10: 320 | D10: =B10*C10 -> 320 | E10: 1 | F10: Shared front desk
A11: Waiting | B11: 1 | C11: 1000 | D11: =B11*C11 -> 1000 | E11: 1 | F11: Divisible by clinic pod
A12: Public Toilet | B12: 8 | C12: 65 | D12: =B12*C12 -> 520 | E12: 1
A13: Self Check-in Kiosk Area | B13: 1 | C13: 120 | D13: =B13*C13 -> 120 | E13: 1
C14: NSF Subtotal: | D14: =SUM(D10:D13) -> 1960
A16: Exam Pods
A17: Standard Exam Room | B17: 48 | C17: 120 | D17: =B17*C17 -> 5760 | E17: 1 | F17: Universal exam room
A18: Procedure Room | B18: 8 | C18: 180 | D18: =B18*C18 -> 1440 | E18: 1 | F18: Minor procedures
A19: Consult Room | B19: 12 | C19: 100 | D19: =B19*C19 -> 1200 | E19: 1 | F19: Provider consult
A20: Nurse Station | B20: 6 | C20: 160 | D20: =B20*C20 -> 960 | E20: 1 | F20: Pod-based
C21: NSF Subtotal: | D21: =SUM(D17:D20) -> 9360
A23: Clinic Support
A24: Clean Supply | B24: 4 | C24: 120 | D24: =B24*C24 -> 480 | E24: 1
A25: Soiled Utility | B25: 4 | C25: 110 | D25: =B25*C25 -> 440 | E25: 1
A26: Medication Room | B26: 3 | C26: 110 | D26: =B26*C26 -> 330 | E26: 1
A27: Team Workroom | B27: 4 | C27: 260 | D27: =B27*C27 -> 1040 | E27: 1
A28: Equipment Storage | B28: 2 | C28: 260 | D28: =B28*C28 -> 520 | E28: 1
C29: NSF Subtotal: | D29: =SUM(D24:D28) -> 2810
C31: NSF Subtotal: | D31: =C3 -> 14130
C32: Grossing Factor: | D32: =C4 -> 1.56
C33: DGSF Subtotal: | D33: =C5 -> 22042.8

Sheet Public Amenities
A1: Public Amenities
B3: Departmental Net Sq. Feet: | C3: =SUM(D15,D23,D29) -> 12830 | D3: Macro Program Placeholder: | E3: =C5 -> 18860.1
B4: Departmental Grossing Factor: | C4: 1.47
B5: Departmental Gross Sq. Feet: | C5: =C3*C4 -> 18860.1
A8: Program | B8: Quantity | C8: NSF/Room | D8: Total NSF | E8: Floor | F8: Comment
A9: Arrival and Lobby
A10: Main Lobby | B10: 1 | C10: 2500 | D10: =B10*C10 -> 2500 | E10: 1 | F10: Major public orientation
A11: Information Desk | B11: 1 | C11: 180 | D11: =B11*C11 -> 180 | E11: 1
A12: Security Screening | B12: 1 | C12: 220 | D12: =B12*C12 -> 220 | E12: 1
A13: Public Waiting | B13: 1 | C13: 1200 | D13: =B13*C13 -> 1200 | E13: 1
A14: Public Toilet Bank | B14: 4 | C14: 220 | D14: =B14*C14 -> 880 | E14: 1
C15: NSF Subtotal: | D15: =SUM(D10:D14) -> 4980
A17: Amenity Areas
A18: Cafeteria Dining | B18: 1 | C18: 2500 | D18: =B18*C18 -> 2500 | E18: 1 | F18: Public and staff
A19: Retail Pharmacy | B19: 1 | C19: 700 | D19: =B19*C19 -> 700 | E19: 1
A20: Gift Shop | B20: 1 | C20: 500 | D20: =B20*C20 -> 500 | E20: 1
A21: Meditation / Chapel | B21: 1 | C21: 650 | D21: =B21*C21 -> 650 | E21: 1 | F21: Quiet zone
A22: Community Room | B22: 2 | C22: 600 | D22: =B22*C22 -> 1200 | E22: 1 | F22: Public education
C23: NSF Subtotal: | D23: =SUM(D18:D22) -> 5550
A25: Vertical Circulation Support
A26: Elevator Lobby | B26: 4 | C26: 450 | D26: =B26*C26 -> 1800 | E26: 1 | F26: Public elevator banks
A27: Wayfinding Alcove | B27: 4 | C27: 80 | D27: =B27*C27 -> 320 | E27: 1
A28: Volunteer Office | B28: 1 | C28: 180 | D28: =B28*C28 -> 180 | E28: 1
C29: NSF Subtotal: | D29: =SUM(D26:D28) -> 2300
C31: NSF Subtotal: | D31: =C3 -> 12830
C32: Grossing Factor: | D32: =C4 -> 1.47
C33: DGSF Subtotal: | D33: =C5 -> 18860.1

Sheet Administration
A1: Administration
B3: Departmental Net Sq. Feet: | C3: =SUM(D15,D23) -> 10470 | D3: Macro Program Placeholder: | E3: =C5 -> 16542.6
B4: Departmental Grossing Factor: | C4: 1.58
B5: Departmental Gross Sq. Feet: | C5: =C3*C4 -> 16542.6
A8: Program | B8: Quantity | C8: NSF/Room | D8: Total NSF | E8: Floor | F8: Comment
A9: Executive and Admin
A10: Open Office Workstations | B10: 60 | C10: 55 | D10: =B10*C10 -> 3300 | E10: 7
A11: Private Office | B11: 18 | C11: 120 | D11: =B11*C11 -> 2160 | E11: 7
A12: Conference Room, Small | B12: 8 | C12: 180 | D12: =B12*C12 -> 1440 | E12: 7
A13: Conference Room, Large | B13: 3 | C13: 450 | D13: =B13*C13 -> 1350 | E13: 7
A14: Board Room | B14: 1 | C14: 700 | D14: =B14*C14 -> 700 | E14: 7
C15: NSF Subtotal: | D15: =SUM(D10:D14) -> 8950
A17: Support
A18: Copy / Print Room | B18: 3 | C18: 100 | D18: =B18*C18 -> 300 | E18: 7
A19: Records Storage | B19: 1 | C19: 400 | D19: =B19*C19 -> 400 | E19: 7
A20: Break Room | B20: 2 | C20: 220 | D20: =B20*C20 -> 440 | E20: 7
A21: Admin Reception | B21: 1 | C21: 160 | D21: =B21*C21 -> 160 | E21: 7
A22: Staff Toilet | B22: 4 | C22: 55 | D22: =B22*C22 -> 220 | E22: 7
C23: NSF Subtotal: | D23: =SUM(D18:D22) -> 1520
C25: NSF Subtotal: | D25: =C3 -> 10470
C26: Grossing Factor: | D26: =C4 -> 1.58
C27: DGSF Subtotal: | D27: =C5 -> 16542.6

Sheet Nutrition and Food Service
A1: Nutrition and Food Service
B3: Departmental Net Sq. Feet: | C3: =SUM(D15,D23,D30) -> 10040 | D3: Macro Program Placeholder: | E3: =C5 -> 16465.6
B4: Departmental Grossing Factor: | C4: 1.64
B5: Departmental Gross Sq. Feet: | C5: =C3*C4 -> 16465.6
A8: Program | B8: Quantity | C8: NSF/Room | D8: Total NSF | E8: Floor | F8: Comment
A9: Kitchen Production
A10: Main Kitchen | B10: 1 | C10: 3000 | D10: =B10*C10 -> 3000 | E10: 1 | F10: Hospital food production
A11: Cold Prep | B11: 1 | C11: 650 | D11: =B11*C11 -> 650 | E11: 1
A12: Hot Prep / Cookline | B12: 1 | C12: 900 | D12: =B12*C12 -> 900 | E12: 1
A13: Bakery / Dessert Prep | B13: 1 | C13: 350 | D13: =B13*C13 -> 350 | E13: 1
A14: Tray Assembly | B14: 1 | C14: 900 | D14: =B14*C14 -> 900 | E14: 1
C15: NSF Subtotal: | D15: =SUM(D10:D14) -> 5800
A17: Storage and Receiving
A18: Dry Food Storage | B18: 1 | C18: 900 | D18: =B18*C18 -> 900 | E18: 1
A19: Walk-in Cooler | B19: 3 | C19: 240 | D19: =B19*C19 -> 720 | E19: 1
A20: Walk-in Freezer | B20: 2 | C20: 240 | D20: =B20*C20 -> 480 | E20: 1
A21: Dock Receiving | B21: 1 | C21: 550 | D21: =B21*C21 -> 550 | E21: 1 | F21: Shared receiving
A22: Cart Wash | B22: 1 | C22: 350 | D22: =B22*C22 -> 350 | E22: 1
C23: NSF Subtotal: | D23: =SUM(D18:D22) -> 3000
A25: Staff Support
A26: Dietitian Office | B26: 4 | C26: 100 | D26: =B26*C26 -> 400 | E26: 1
A27: Food Service Office | B27: 3 | C27: 100 | D27: =B27*C27 -> 300 | E27: 1
A28: Staff Lockers | B28: 1 | C28: 300 | D28: =B28*C28 -> 300 | E28: 1
A29: Staff Break | B29: 1 | C29: 240 | D29: =B29*C29 -> 240 | E29: 1
C30: NSF Subtotal: | D30: =SUM(D26:D29) -> 1240
C32: NSF Subtotal: | D32: =C3 -> 10040
C33: Grossing Factor: | D33: =C4 -> 1.64
C34: DGSF Subtotal: | D34: =C5 -> 16465.6

Sheet Materials Management
A1: Materials Management
B3: Departmental Net Sq. Feet: | C3: =SUM(D14,D22,D28) -> 10910 | D3: Macro Program Placeholder: | E3: =C5 -> 15274
B4: Departmental Grossing Factor: | C4: 1.4
B5: Departmental Gross Sq. Feet: | C5: =C3*C4 -> 15274
A8: Program | B8: Quantity | C8: NSF/Room | D8: Total NSF | E8: Floor | F8: Comment
A9: Receiving
A10: Loading Dock | B10: 1 | C10: 1800 | D10: =B10*C10 -> 1800 | E10: 1 | F10: Shared service yard
A11: Receiving Staging | B11: 1 | C11: 1200 | D11: =B11*C11 -> 1200 | E11: 1
A12: Vendor Check-in | B12: 1 | C12: 120 | D12: =B12*C12 -> 120 | E12: 1
A13: Pallet Breakdown | B13: 1 | C13: 600 | D13: =B13*C13 -> 600 | E13: 1
C14: NSF Subtotal: | D14: =SUM(D10:D13) -> 3720
A16: Storage and Distribution
A17: Central Supply Warehouse | B17: 1 | C17: 3500 | D17: =B17*C17 -> 3500 | E17: 1 | F17: Bulk storage
A18: Linen Storage | B18: 1 | C18: 900 | D18: =B18*C18 -> 900 | E18: 1
A19: Medical Gas Cylinder Storage | B19: 1 | C19: 350 | D19: =B19*C19 -> 350 | E19: 1 | F19: Ventilated
A20: Equipment Depot | B20: 1 | C20: 1200 | D20: =B20*C20 -> 1200 | E20: 1 | F20: Beds and pumps
A21: Courier Dispatch | B21: 1 | C21: 220 | D21: =B21*C21 -> 220 | E21: 1
C22: NSF Subtotal: | D22: =SUM(D17:D21) -> 6170
A24: Support
A25: Materials Office | B25: 4 | C25: 100 | D25: =B25*C25 -> 400 | E25: 1
A26: Staff Lockers | B26: 1 | C26: 220 | D26: =B26*C26 -> 220 | E26: 1
A27: Waste Holding | B27: 1 | C27: 400 | D27: =B27*C27 -> 400 | E27: 1
C28: NSF Subtotal: | D28: =SUM(D25:D27) -> 1020
C30: NSF Subtotal: | D30: =C3 -> 10910
C31: Grossing Factor: | D31: =C4 -> 1.4
C32: DGSF Subtotal: | D32: =C5 -> 15274

Sheet Environmental Services
A1: Environmental Services
B3: Departmental Net Sq. Feet: | C3: =SUM(D14,D21,D27) -> 5890 | D3: Macro Program Placeholder: | E3: =C5 -> 9659.6
B4: Departmental Grossing Factor: | C4: 1.64
B5: Departmental Gross Sq. Feet: | C5: =C3*C4 -> 9659.6
A8: Program | B8: Quantity | C8: NSF/Room | D8: Total NSF | E8: Floor | F8: Comment
A9: Housekeeping
A10: EVS Office | B10: 1 | C10: 180 | D10: =B10*C10 -> 180 | E10: 1
A11: Housekeeping Closet | B11: 24 | C11: 45 | D11: =B11*C11 -> 1080 | E11: 1 | F11: Distributed by floor
A12: Clean Linen Room | B12: 8 | C12: 120 | D12: =B12*C12 -> 960 | E12: 1 | F12: Distributed
A13: Soiled Linen Holding | B13: 8 | C13: 100 | D13: =B13*C13 -> 800 | E13: 1 | F13: Distributed
C14: NSF Subtotal: | D14: =SUM(D10:D13) -> 3020
A16: Waste Management
A17: General Waste Holding | B17: 1 | C17: 550 | D17: =B17*C17 -> 550 | E17: 1
A18: Regulated Medical Waste | B18: 1 | C18: 350 | D18: =B18*C18 -> 350 | E18: 1 | F18: Controlled access
A19: Recycling Holding | B19: 1 | C19: 300 | D19: =B19*C19 -> 300 | E19: 1
A20: Trash Compactor Room | B20: 1 | C20: 450 | D20: =B20*C20 -> 450 | E20: 1
C21: NSF Subtotal: | D21: =SUM(D17:D20) -> 1650
A23: Support
A24: EVS Equipment Storage | B24: 1 | C24: 700 | D24: =B24*C24 -> 700 | E24: 1 | F24: Carts and machines
A25: Staff Lockers | B25: 1 | C25: 300 | D25: =B25*C25 -> 300 | E25: 1
A26: Staff Break | B26: 1 | C26: 220 | D26: =B26*C26 -> 220 | E26: 1
C27: NSF Subtotal: | D27: =SUM(D24:D26) -> 1220
C29: NSF Subtotal: | D29: =C3 -> 5890
C30: Grossing Factor: | D30: =C4 -> 1.64
C31: DGSF Subtotal: | D31: =C5 -> 9659.6

Sheet Facilities MEP and HVAC
A1: Facilities MEP and HVAC
B3: Departmental Net Sq. Feet: | C3: =SUM(D15,D23,D30,D37) -> 21740 | D3: Macro Program Placeholder: | E3: =C5 -> 35001.4
B4: Departmental Grossing Factor: | C4: 1.61
B5: Departmental Gross Sq. Feet: | C5: =C3*C4 -> 35001.4
A8: Program | B8: Quantity | C8: NSF/Room | D8: Total NSF | E8: Floor | F8: Comment
A9: Mechanical / HVAC
A10: Central Mechanical Room | B10: 1 | C10: 4500 | D10: =B10*C10 -> 4500 | E10: 1 | F10: Air handling units
A11: AHU Room Level 2 | B11: 1 | C11: 2500 | D11: =B11*C11 -> 2500 | E11: 1 | F11: Surgical air systems
A12: AHU Room Level 5 | B12: 1 | C12: 2200 | D12: =B12*C12 -> 2200 | E12: 1 | F12: Inpatient air systems
A13: Exhaust Fan Room | B13: 1 | C13: 800 | D13: =B13*C13 -> 800 | E13: 1 | F13: Roof-level equipment
A14: Humidification / Water Treatment | B14: 1 | C14: 600 | D14: =B14*C14 -> 600 | E14: 1
C15: NSF Subtotal: | D15: =SUM(D10:D14) -> 10600
A17: Electrical
A18: Main Electrical Room | B18: 1 | C18: 1800 | D18: =B18*C18 -> 1800 | E18: 1 | F18: Utility service entrance
A19: Emergency Generator Room | B19: 1 | C19: 1600 | D19: =B19*C19 -> 1600 | E19: 1 | F19: Acoustic separation
A20: Automatic Transfer Switch Room | B20: 1 | C20: 450 | D20: =B20*C20 -> 450 | E20: 1
A21: Electrical Closet | B21: 12 | C21: 120 | D21: =B21*C21 -> 1440 | E21: 1 | F21: Stacked by floor
A22: UPS Room | B22: 1 | C22: 500 | D22: =B22*C22 -> 500 | E22: 1 | F22: Critical systems
C23: NSF Subtotal: | D23: =SUM(D18:D22) -> 5790
A25: Plumbing and Medical Gas
A26: Plumbing Equipment Room | B26: 1 | C26: 1200 | D26: =B26*C26 -> 1200 | E26: 1 | F26: Pumps and heaters
A27: Medical Gas Manifold | B27: 1 | C27: 500 | D27: =B27*C27 -> 500 | E27: 1 | F27: Exterior ventilation
A28: Vacuum Pump Room | B28: 1 | C28: 450 | D28: =B28*C28 -> 450 | E28: 1
A29: Fire Pump Room | B29: 1 | C29: 600 | D29: =B29*C29 -> 600 | E29: 1
C30: NSF Subtotal: | D30: =SUM(D26:D29) -> 2750
A32: Facilities Support
A33: Facilities Office | B33: 6 | C33: 100 | D33: =B33*C33 -> 600 | E33: 1
A34: Maintenance Shop | B34: 1 | C34: 900 | D34: =B34*C34 -> 900 | E34: 1
A35: Parts Storage | B35: 1 | C35: 700 | D35: =B35*C35 -> 700 | E35: 1
A36: Janitor Supply Bulk Storage | B36: 1 | C36: 400 | D36: =B36*C36 -> 400 | E36: 1
C37: NSF Subtotal: | D37: =SUM(D33:D36) -> 2600
C39: NSF Subtotal: | D39: =C3 -> 21740
C40: Grossing Factor: | D40: =C4 -> 1.61
C41: DGSF Subtotal: | D41: =C5 -> 35001.4

Sheet IT Security and Command Center
A1: IT Security and Command Center
B3: Departmental Net Sq. Feet: | C3: =SUM(D14,D21,D28) -> 7310 | D3: Macro Program Placeholder: | E3: =C5 -> 10965
B4: Departmental Grossing Factor: | C4: 1.5
B5: Departmental Gross Sq. Feet: | C5: =C3*C4 -> 10965
A8: Program | B8: Quantity | C8: NSF/Room | D8: Total NSF | E8: Floor | F8: Comment
A9: IT Infrastructure
A10: Main Data Center | B10: 1 | C10: 1600 | D10: =B10*C10 -> 1600 | E10: 1 | F10: Redundant cooling
A11: Telecom Entrance Room | B11: 1 | C11: 450 | D11: =B11*C11 -> 450 | E11: 1
A12: IDF Closet | B12: 16 | C12: 90 | D12: =B12*C12 -> 1440 | E12: 1 | F12: Distributed closets
A13: Network Operations Center | B13: 1 | C13: 500 | D13: =B13*C13 -> 500 | E13: 1
C14: NSF Subtotal: | D14: =SUM(D10:D13) -> 3990
A16: Security Operations
A17: Security Command Center | B17: 1 | C17: 650 | D17: =B17*C17 -> 650 | E17: 1 | F17: CCTV monitoring
A18: Badge Office | B18: 1 | C18: 160 | D18: =B18*C18 -> 160 | E18: 1
A19: Holding Interview Room | B19: 2 | C19: 120 | D19: =B19*C19 -> 240 | E19: 1
A20: Security Equipment Storage | B20: 1 | C20: 220 | D20: =B20*C20 -> 220 | E20: 1
C21: NSF Subtotal: | D21: =SUM(D17:D20) -> 1270
A23: Clinical Technology Support
A24: Biomedical Engineering Shop | B24: 1 | C24: 900 | D24: =B24*C24 -> 900 | E24: 1
A25: Device Testing Lab | B25: 1 | C25: 300 | D25: =B25*C25 -> 300 | E25: 1
A26: Spare Device Storage | B26: 1 | C26: 500 | D26: =B26*C26 -> 500 | E26: 1
A27: IT Help Desk | B27: 1 | C27: 350 | D27: =B27*C27 -> 350 | E27: 1
C28: NSF Subtotal: | D28: =SUM(D24:D27) -> 2050
C30: NSF Subtotal: | D30: =C3 -> 7310
C31: Grossing Factor: | D31: =C4 -> 1.5
C32: DGSF Subtotal: | D32: =C5 -> 10965

Sheet Education and Conference
A1: Education and Conference
B3: Departmental Net Sq. Feet: | C3: =SUM(D14,D21,D27) -> 10270 | D3: Macro Program Placeholder: | E3: =C5 -> 14891.5
B4: Departmental Grossing Factor: | C4: 1.45
B5: Departmental Gross Sq. Feet: | C5: =C3*C4 -> 14891.5
A8: Program | B8: Quantity | C8: NSF/Room | D8: Total NSF | E8: Floor | F8: Comment
A9: Teaching Spaces
A10: Simulation Lab | B10: 1 | C10: 900 | D10: =B10*C10 -> 900 | E10: 7 | F10: Mock clinical room
A11: Classroom | B11: 4 | C11: 600 | D11: =B11*C11 -> 2400 | E11: 7 | F11: Flexible training
A12: Computer Training Room | B12: 2 | C12: 450 | D12: =B12*C12 -> 900 | E12: 7
A13: Skills Lab | B13: 1 | C13: 700 | D13: =B13*C13 -> 700 | E13: 7
C14: NSF Subtotal: | D14: =SUM(D10:D13) -> 4900
A16: Conference Center
A17: Auditorium | B17: 1 | C17: 1800 | D17: =B17*C17 -> 1800 | E17: 7 | F17: Hospital-wide meetings
A18: Pre-function Area | B18: 1 | C18: 900 | D18: =B18*C18 -> 900 | E18: 7
A19: Conference Room | B19: 6 | C19: 250 | D19: =B19*C19 -> 1500 | E19: 7
A20: Catering Pantry | B20: 1 | C20: 250 | D20: =B20*C20 -> 250 | E20: 7
C21: NSF Subtotal: | D21: =SUM(D17:D20) -> 4450
A23: Support
A24: Storage | B24: 2 | C24: 180 | D24: =B24*C24 -> 360 | E24: 7 | F24: Tables and chairs
A25: Admin Office | B25: 3 | C25: 100 | D25: =B25*C25 -> 300 | E25: 7
A26: Public Toilet | B26: 4 | C26: 65 | D26: =B26*C26 -> 260 | E26: 7
C27: NSF Subtotal: | D27: =SUM(D24:D26) -> 920
C29: NSF Subtotal: | D29: =C3 -> 10270
C30: Grossing Factor: | D30: =C4 -> 1.45
C31: DGSF Subtotal: | D31: =C5 -> 14891.5

Sheet Renal Dialysis
A1: Renal Dialysis
B3: Departmental Net Sq. Feet: | C3: =SUM(D14,D21,D29) -> 6075 | D3: Macro Program Placeholder: | E3: =C5 -> 10266.75
B4: Departmental Grossing Factor: | C4: 1.69
B5: Departmental Gross Sq. Feet: | C5: =C3*C4 -> 10266.75
A8: Program | B8: Quantity | C8: NSF/Room | D8: Total NSF | E8: Floor | F8: Comment
A9: Public Area
A10: Reception | B10: 1 | C10: 150 | D10: =B10*C10 -> 150 | E10: 1
A11: Waiting | B11: 1 | C11: 420 | D11: =B11*C11 -> 420 | E11: 1
A12: Public Toilet | B12: 3 | C12: 65 | D12: =B12*C12 -> 195 | E12: 1
A13: Consult Room | B13: 2 | C13: 120 | D13: =B13*C13 -> 240 | E13: 1
C14: NSF Subtotal: | D14: =SUM(D10:D13) -> 1005
A16: Treatment
A17: Dialysis Station | B17: 24 | C17: 110 | D17: =B17*C17 -> 2640 | E17: 1 | F17: Patient recliner and equipment
A18: Isolation Dialysis Room | B18: 2 | C18: 160 | D18: =B18*C18 -> 320 | E18: 1
A19: Nurse Station | B19: 2 | C19: 200 | D19: =B19*C19 -> 400 | E19: 1
A20: Water Treatment Room | B20: 1 | C20: 500 | D20: =B20*C20 -> 500 | E20: 1 | F20: Critical infrastructure
C21: NSF Subtotal: | D21: =SUM(D17:D20) -> 3860
A23: Support
A24: Clean Supply | B24: 2 | C24: 140 | D24: =B24*C24 -> 280 | E24: 1
A25: Soiled Utility | B25: 2 | C25: 120 | D25: =B25*C25 -> 240 | E25: 1
A26: Medication Room | B26: 1 | C26: 120 | D26: =B26*C26 -> 120 | E26: 1
A27: Equipment Storage | B27: 1 | C27: 350 | D27: =B27*C27 -> 350 | E27: 1
A28: Staff Workroom | B28: 1 | C28: 220 | D28: =B28*C28 -> 220 | E28: 1
C29: NSF Subtotal: | D29: =SUM(D24:D28) -> 1210
C31: NSF Subtotal: | D31: =C3 -> 6075
C32: Grossing Factor: | D32: =C4 -> 1.69
C33: DGSF Subtotal: | D33: =C5 -> 10266.75
